Workbook

Sheet region
A1: geo | B1: name | C1: four_regions | D1: six_regions | E1: eight_regions | F1: members_oecd_g77 | G1: Latitude | H1: Longitude | I1: UN member since | J1: World bank region | K1: World bank, 4 income groups 2017 | L1: World bank, 3 income groups 2017
A2: afg | B2: Afghanistan | C2: asia | D2: south_asia | E2: asia_west | F2: g77 | G2: 33 | H2: 66 | I2: 17125 | J2: South Asia | K2: Low income
A3: alb | B3: Albania | C3: europe | D3: europe_central_asia | E3: europe_east | F3: others | G3: 41 | H3: 20 | I3: 20437 | J3: Europe & Central Asia | K3: Upper middle income
A4: dza | B4: Algeria | C4: africa | D4: middle_east_north_africa | E4: africa_north | F4: g77 | G4: 28 | H4: 3 | I4: 22927 | J4: Middle East & North Africa | K4: Upper middle income
A5: and | B5: Andorra | C5: europe | D5: europe_central_asia | E5: europe_west | F5: others | G5: 42.50779 | H5: 1.52109 | I5: 34178 | J5: Europe & Central Asia | K5: High income
A6: ago | B6: Angola | C6: africa | D6: sub_saharan_africa | E6: africa_sub_saharan | F6: g77 | G6: -12.5 | H6: 18.5 | I6: 28095 | J6: Sub-Saharan Africa | K6: Lower middle income
A7: atg | B7: Antigua and Barbuda | C7: americas | D7: america | E7: america_north | F7: g77 | G7: 17.05 | H7: -61.8 | I7: 29901 | J7: Latin America & Caribbean | K7: High income
A8: arg | B8: Argentina | C8: americas | D8: america | E8: america_south | F8: g77 | G8: -34 | H8: -64 | I8: 16734 | J8: Latin America & Caribbean | K8: Upper middle income
A9: arm | B9: Armenia | C9: europe | D9: europe_central_asia | E9: europe_east | F9: others | G9: 40.25 | H9: 45 | I9: 33665 | J9: Europe & Central Asia | K9: Lower middle income
A10: aus | B10: Australia | C10: asia | D10: east_asia_pacific | E10: east_asia_pacific | F10: oecd | G10: -25 | H10: 135 | I10: 16742 | J10: East Asia & Pacific | K10: High income
A11: aut | B11: Austria | C11: europe | D11: europe_central_asia | E11: europe_west | F11: oecd | G11: 47.33333 | H11: 13.33333 | I11: 20437 | J11: Europe & Central Asia | K11: High income
A12: aze | B12: Azerbaijan | C12: europe | D12: europe_central_asia | E12: europe_east | F12: others | G12: 40.5 | H12: 47.5 | I12: 33665 | J12: Europe & Central Asia | K12: Upper middle income
A13: bhs | B13: Bahamas | C13: americas | D13: america | E13: america_north | F13: g77 | G13: 25.04082 | H13: -77.37122 | I13: 26894 | J13: Latin America & Caribbean | K13: High income
... A73: hti | B73: Haiti | C73: americas | D73: america | E73: america_north | F73: g77 | G73: 19 | H73: -72.41667 | I73: 16734 | J73: Latin America & Caribbean | K73: Low income
A74: hos | B74: Holy See | C74: europe | D74: europe_central_asia | E74: europe_west | F74: others | G74: 41.90236 | H74: 12.45332
A75: hnd | B75: Honduras | C75: americas | D75: america | E75: america_north | F75: g77 | G75: 15 | H75: -86.5 | I75: 16788 | J75: Latin America & Caribbean | K75: Lower middle income
A76: hkg | B76: Hong Kong, China | C76: asia | D76: east_asia_pacific | E76: east_asia_pacific | F76: others | G76: 22.28552 | H76: 114.15769 | J76: East Asia & Pacific | K76: High income
A77: hun | B77: Hungary | C77: europe | D77: europe_central_asia | E77: europe_east | F77: oecd | G77: 47 | H77: 20 | I77: 20437 | J77: Europe & Central Asia | K77: High income
A78: isl | B78: Iceland | C78: europe | D78: europe_central_asia | E78: europe_west | F78: oecd | G78: 65 | H78: -18 | I78: 17125 | J78: Europe & Central Asia | K78: High income
A79: ind | B79: India | C79: asia | D79: south_asia | E79: asia_west | F79: g77 | G79: 22 | H79: 79 | I79: 16740 | J79: South Asia | K79: Lower middle income
A80: idn | B80: Indonesia | C80: asia | D80: east_asia_pacific | E80: east_asia_pacific | F80: g77 | G80: -5 | H80: 120 | I80: 18534 | J80: East Asia & Pacific | K80: Lower middle income
A81: irn | B81: Iran | C81: asia | D81: middle_east_north_africa | E81: asia_west | F81: g77 | G81: 32 | H81: 53 | I81: 16734 | J81: Middle East & North Africa | K81: Upper middle income
A82: irq | B82: Iraq | C82: asia | D82: middle_east_north_africa | E82: asia_west | F82: g77 | G82: 33 | H82: 44 | I82: 16792 | J82: Middle East & North Africa | K82: Upper middle income
A83: irl | B83: Ireland | C83: europe | D83: europe_central_asia | E83: europe_west | F83: oecd | G83: 53 | H83: -8 | I83: 20437 | J83: Europe & Central Asia | K83: High income
A84: isr | B84: Israel | C84: asia | D84: middle_east_north_africa | E84: asia_west | F84: others | G84: 31.5 | H84: 34.75 | I84: 18029 | J84: Middle East & North Africa | K84: High income
A85: ita | B85: Italy | C85: europe | D85: europe_central_asia | E85: europe_west | F85: oecd | G85: 42.83333 | H85: 12.83333 | I85: 20437 | J85: Europe & Central Asia | K85: High income
A86: jam | B86: Jamaica | C86: americas | D86: america | E86: america_north | F86: g77 | G86: 18.16667 | H86: -77.25 | I86: 22907 | J86: Latin America & Caribbean | K86: Upper middle income
A87: jpn | B87: Japan | C87: asia | D87: east_asia_pacific | E87: east_asia_pacific | F87: oecd | G87: 35.68536 | H87: 139.75309 | I87: 20807 | J87: East Asia & Pacific | K87: High income
A88: jor | B88: Jordan | C88: asia | D88: middle_east_north_africa | E88: asia_west | F88: g77 | G88: 31 | H88: 36 | I88: 20437 | J88: Middle East & North Africa | K88: Lower middle income
... A171: syr | B171: Syria | C171: asia | D171: middle_east_north_africa | E171: asia_west | F171: g77 | G171: 35 | H171: 38 | I171: 16734 | J171: Middle East & North Africa | K171: Lower middle income
A172: twn | B172: Taiwan | C172: asia | D172: east_asia_pacific | E172: east_asia_pacific | F172: others | G172: 24 | H172: 121 | J172: East Asia & Pacific | K172: High income
A173: tjk | B173: Tajikistan | C173: asia | D173: europe_central_asia | E173: asia_west | F173: others | G173: 39 | H173: 71 | I173: 33665 | J173: Europe & Central Asia | K173: Lower middle income
A174: tza | B174: Tanzania | C174: africa | D174: sub_saharan_africa | E174: africa_sub_saharan | F174: g77 | G174: -6 | H174: 35 | I174: 22629 | J174: Sub-Saharan Africa | K174: Low income
A175: tha | B175: Thailand | C175: asia | D175: east_asia_pacific | E175: east_asia_pacific | F175: g77 | G175: 15.5 | H175: 101 | I175: 17152 | J175: East Asia & Pacific | K175: Upper middle income
A176: tls | B176: Timor-Leste | C176: asia | D176: east_asia_pacific | E176: east_asia_pacific | F176: g77 | G176: -8.83333 | H176: 125.75 | I176: 37526 | J176: East Asia & Pacific | K176: Lower middle income
A177: tgo | B177: Togo | C177: africa | D177: sub_saharan_africa | E177: africa_sub_saharan | F177: g77 | G177: 8.66667 | H177: 1.08333 | I177: 22179 | J177: Sub-Saharan Africa | K177: Low income
A178: ton | B178: Tonga | C178: asia | D178: east_asia_pacific | E178: east_asia_pacific | F178: g77 | G178: -20 | H178: -175 | I178: 36417 | J178: East Asia & Pacific | K178: Upper middle income
A179: tto | B179: Trinidad and Tobago | C179: americas | D179: america | E179: america_north | F179: g77 | G179: 11 | H179: -61 | I179: 22907 | J179: Latin America & Caribbean | K179: High income
A180: tun | B180: Tunisia | C180: africa | D180: middle_east_north_africa | E180: africa_north | F180: g77 | G180: 34 | H180: 9 | I180: 20771 | J180: Middle East & North Africa | K180: Lower middle income
A181: tur | B181: Turkey | C181: europe | D181: europe_central_asia | E181: europe_east | F181: oecd | G181: 39 | H181: 35 | I181: 16734 | J181: Europe & Central Asia | K181: Upper middle income
...

Sheet p.greggio
A1: Crude oil production (Mt)
B3: 2018
A4: World | B4: 4489.2039
A5: OECD | B5: 1217.4019
A6: G7 | B6: 996.34825
A7: BRICS | B7: 927.52452
A8: Europe | B8: 168.39533
A9: European Union | B9: 80.078139
A10: Belgium | B10: 0
A11: Czech Republic | B11: 0.20261952
A12: France | B12: 0.97695967
A13: Germany | B13: 3.6050814
A14: Italy | B14: 5.137626
A15: Netherlands | B15: 1.4913505
... A61: United Arab Emirates | B61: 180.84693

Sheet p.raffinati
A1: Refined oil products production (Mt)
B3: 2018
A4: World | B4: 4305.4899
A5: OECD | B5: 2027.2709
A6: G7 | B6: 1418.6799
A7: BRICS | B7: 1263.638
A8: Europe | B8: 678.44254
A9: European Union | B9: 626.71174
A10: Belgium | B10: 33.923
A11: Czech Republic | B11: 7.8425204
A12: France | B12: 55.098914
A13: Germany | B13: 92.491387
A14: Italy | B14: 72.291741
A15: Netherlands | B15: 60.946911
... A61: United Arab Emirates | B61: 58.39285

Sheet p.coalignite
A1: Coal and lignite production (Mt)
B3: 2018
A4: World | B4: 7683.282
A5: OECD | B5: 1768.2801
A6: G7 | B6: 910.4137
A7: BRICS | B7: 4911.0234
A8: Europe | B8: 628.56506
A9: European Union | B9: 472.63748
A10: Belgium | B10: 0.018285714
A11: Czech Republic | B11: 43.739529
A12: France | B12: 0
A13: Germany | B13: 168.79785
A14: Italy | B14: 0
A15: Netherlands | B15: 0
... A61: United Arab Emirates | B61: 0

Sheet p.gas
A1: Natural gas production (bcm)
B3: 2018
A4: World | B4: 3975.3932
A5: OECD | B5: 1453.809
A6: G7 | B6: 1107.7047
A7: BRICS | B7: 957.28541
A8: Europe | B8: 240.31282
A9: European Union | B9: 112.06751
A10: Belgium | B10: 0
A11: Czech Republic | B11: 0.21802916
A12: France | B12: 0.021736921
A13: Germany | B13: 6.8669018
A14: Italy | B14: 5.4502579
A15: Netherlands | B15: 31.340703
... A61: United Arab Emirates | B61: 61.733545

Sheet p.ele
A1: Electricity production (TWh)
B3: 2018
A4: World | B4: 26590.339
A5: OECD | B5: 11229.839
A6: G7 | B6: 8037.4926
A7: BRICS | B7: 10715.201
A8: Europe | B8: 3883.4599
A9: European Union | B9: 3277.9671
A10: Belgium | B10: 74.460825
A11: Czech Republic | B11: 88.012739
A12: France | B12: 571.35027
A13: Germany | B13: 647.37896
A14: Italy | B14: 290.61232
A15: Netherlands | B15: 117.24182
... A61: United Arab Emirates | B61: 136.93033

Sheet s.elerinnov
A1: Share of renewables in electricity production (%)
B3: 2018
A4: World | B4: 25.603861
A5: OECD | B5: 26.139697
A6: G7 | B6: 24.633017
A7: BRICS | B7: 26.738654
A8: Europe | B8: 36.395334
A9: European Union | B9: 32.716815
A10: Belgium | B10: 23.302486
A11: Czech Republic | B11: 11.904241
A12: France | B12: 19.938214
A13: Germany | B13: 35.996468
A14: Italy | B14: 39.867512
A15: Netherlands | B15: 15.718127
... A61: United Arab Emirates | B61: 0.442572

Sheet s.windsolar
A1: Share of wind and solar in electricity production (%)
B3: 2018
A4: World | B4: 7.473321
A5: OECD | B5: 10.404753
A6: G7 | B6: 10.636281
A7: BRICS | B7: 6.685472
A8: Europe | B8: 14.660576
A9: European Union | B9: 15.809619
A10: Belgium | B10: 14.752632
A11: Czech Republic | B11: 3.459028
A12: France | B12: 6.84479
A13: Germany | B13: 25.025896
A14: Italy | B14: 16.335108
A15: Netherlands | B15: 11.721872
... A61: United Arab Emirates | B61: 0.442572

Sheet co2
A1: CO2 emissions from fuel combustion (MtCO2)
B3: 2018
A4: World | B4: 32915.94
A5: OECD | B5: 12151.12
A6: G7 | B6: 8560.11
A7: BRICS | B7: 14345.28
A8: Europe | B8: 3838.92
A9: European Union | B9: 3283.75
A10: Belgium | B10: 96.9
A11: Czech Republic | B11: 100.91
A12: France | B12: 301.87
A13: Germany | B13: 732.82
A14: Italy | B14: 326.56
A15: Netherlands | B15: 179.59
... A61: United Arab Emirates | B61: 188.5

Sheet unionedati
A1: country | B1: region | C1: p.greggio | D1: p.raffinati | E1: p.coalignite | F1: p.gas | G1: p.ele | H1: s.elerinnov | I1: s.windsolar | J1: co2
A2: Belgium | B2: =VLOOKUP(A2,region!$B$2:$M$198,2,FALSE) -> europe | C2: =VLOOKUP(A2,p.greggio!A10:B67,2,FALSE) -> 0 | D2: =VLOOKUP(A2,p.raffinati!A10:B67,2,FALSE) -> 33.923 | E2: =VLOOKUP(A2,p.coalignite!A10:B67,2,FALSE) -> 0.018285714 | F2: =VLOOKUP(A2,p.gas!A10:B67,2,FALSE) -> 0 | G2: =VLOOKUP(A2,p.ele!A10:B67,2,FALSE) -> 74.460825 | H2: =VLOOKUP(A2,s.elerinnov!A10:B67,2,FALSE)/100 -> 0.23302486 | I2: =VLOOKUP(A2,s.windsolar!A10:B67,2,FALSE)/100 -> 0.14752632 | J2: =VLOOKUP(A2,'co2'!A10:B67,2,FALSE) -> 96.9
A3: Czech Republic | B3: =VLOOKUP(A3,region!$B$2:$M$198,2,FALSE) -> europe | C3: =VLOOKUP(A3,p.greggio!A11:B68,2,FALSE) -> 0.20261952 | D3: =VLOOKUP(A3,p.raffinati!A11:B68,2,FALSE) -> 7.8425204 | E3: =VLOOKUP(A3,p.coalignite!A11:B68,2,FALSE) -> 43.739529 | F3: =VLOOKUP(A3,p.gas!A11:B68,2,FALSE) -> 0.21802916 | G3: =VLOOKUP(A3,p.ele!A11:B68,2,FALSE) -> 88.012739 | H3: =VLOOKUP(A3,s.elerinnov!A11:B68,2,FALSE)/100 -> 0.11904241 | I3: =VLOOKUP(A3,s.windsolar!A11:B68,2,FALSE)/100 -> 0.03459028 | J3: =VLOOKUP(A3,'co2'!A11:B68,2,FALSE) -> 100.91
A4: France | B4: =VLOOKUP(A4,region!$B$2:$M$198,2,FALSE) -> europe | C4: =VLOOKUP(A4,p.greggio!A12:B69,2,FALSE) -> 0.97695967 | D4: =VLOOKUP(A4,p.raffinati!A12:B69,2,FALSE) -> 55.098914 | E4: =VLOOKUP(A4,p.coalignite!A12:B69,2,FALSE) -> 0 | F4: =VLOOKUP(A4,p.gas!A12:B69,2,FALSE) -> 0.021736921 | G4: =VLOOKUP(A4,p.ele!A12:B69,2,FALSE) -> 571.35027 | H4: =VLOOKUP(A4,s.elerinnov!A12:B69,2,FALSE)/100 -> 0.19938214 | I4: =VLOOKUP(A4,s.windsolar!A12:B69,2,FALSE)/100 -> 0.0684479 | J4: =VLOOKUP(A4,'co2'!A12:B69,2,FALSE) -> 301.87
A5: Germany | B5: =VLOOKUP(A5,region!$B$2:$M$198,2,FALSE) -> europe | C5: =VLOOKUP(A5,p.greggio!A13:B70,2,FALSE) -> 3.6050814 | D5: =VLOOKUP(A5,p.raffinati!A13:B70,2,FALSE) -> 92.491387 | E5: =VLOOKUP(A5,p.coalignite!A13:B70,2,FALSE) -> 168.79785 | F5: =VLOOKUP(A5,p.gas!A13:B70,2,FALSE) -> 6.8669018 | G5: =VLOOKUP(A5,p.ele!A13:B70,2,FALSE) -> 647.37896 | H5: =VLOOKUP(A5,s.elerinnov!A13:B70,2,FALSE)/100 -> 0.35996468 | I5: =VLOOKUP(A5,s.windsolar!A13:B70,2,FALSE)/100 -> 0.25025896 | J5: =VLOOKUP(A5,'co2'!A13:B70,2,FALSE) -> 732.82
A6: Italy | B6: =VLOOKUP(A6,region!$B$2:$M$198,2,FALSE) -> europe | C6: =VLOOKUP(A6,p.greggio!A14:B71,2,FALSE) -> 5.137626 | D6: =VLOOKUP(A6,p.raffinati!A14:B71,2,FALSE) -> 72.291741 | E6: =VLOOKUP(A6,p.coalignite!A14:B71,2,FALSE) -> 0 | F6: =VLOOKUP(A6,p.gas!A14:B71,2,FALSE) -> 5.4502579 | G6: =VLOOKUP(A6,p.ele!A14:B71,2,FALSE) -> 290.61232 | H6: =VLOOKUP(A6,s.elerinnov!A14:B71,2,FALSE)/100 -> 0.39867512 | I6: =VLOOKUP(A6,s.windsolar!A14:B71,2,FALSE)/100 -> 0.16335108 | J6: =VLOOKUP(A6,'co2'!A14:B71,2,FALSE) -> 326.56
A7: Netherlands | B7: =VLOOKUP(A7,region!$B$2:$M$198,2,FALSE) -> europe | C7: =VLOOKUP(A7,p.greggio!A15:B72,2,FALSE) -> 1.4913505 | D7: =VLOOKUP(A7,p.raffinati!A15:B72,2,FALSE) -> 60.946911 | E7: =VLOOKUP(A7,p.coalignite!A15:B72,2,FALSE) -> 0 | F7: =VLOOKUP(A7,p.gas!A15:B72,2,FALSE) -> 31.340703 | G7: =VLOOKUP(A7,p.ele!A15:B72,2,FALSE) -> 117.24182 | H7: =VLOOKUP(A7,s.elerinnov!A15:B72,2,FALSE)/100 -> 0.15718127 | I7: =VLOOKUP(A7,s.windsolar!A15:B72,2,FALSE)/100 -> 0.11721872 | J7: =VLOOKUP(A7,'co2'!A15:B72,2,FALSE) -> 179.59
A8: Poland | B8: =VLOOKUP(A8,region!$B$2:$M$198,2,FALSE) -> europe | C8: =VLOOKUP(A8,p.greggio!A16:B73,2,FALSE) -> 1.6110294 | D8: =VLOOKUP(A8,p.raffinati!A16:B73,2,FALSE) -> 28.654596 | E8: =VLOOKUP(A8,p.coalignite!A16:B73,2,FALSE) -> 122.82071 | F8: =VLOOKUP(A8,p.gas!A16:B73,2,FALSE) -> 5.614889 | G8: =VLOOKUP(A8,p.ele!A16:B73,2,FALSE) -> 169.80984 | H8: =VLOOKUP(A8,s.elerinnov!A16:B73,2,FALSE)/100 -> 0.12983093 | I8: =VLOOKUP(A8,s.windsolar!A16:B73,2,FALSE)/100 -> 0.07727818 | J8: =VLOOKUP(A8,'co2'!A16:B73,2,FALSE) -> 329.15
A9: Portugal | B9: =VLOOKUP(A9,region!$B$2:$M$198,2,FALSE) -> europe | C9: =VLOOKUP(A9,p.greggio!A17:B74,2,FALSE) -> 0.066196388 | D9: =VLOOKUP(A9,p.raffinati!A17:B74,2,FALSE) -> 13.983421 | E9: =VLOOKUP(A9,p.coalignite!A17:B74,2,FALSE) -> 0 | F9: =VLOOKUP(A9,p.gas!A17:B74,2,FALSE) -> 0 | G9: =VLOOKUP(A9,p.ele!A17:B74,2,FALSE) -> 59.770922 | H9: =VLOOKUP(A9,s.elerinnov!A17:B74,2,FALSE)/100 -> 0.52175637 | I9: =VLOOKUP(A9,s.windsolar!A17:B74,2,FALSE)/100 -> 0.23370864 | J9: =VLOOKUP(A9,'co2'!A17:B74,2,FALSE) -> 50.19
A10: Romania | B10: =VLOOKUP(A10,region!$B$2:$M$198,2,FALSE) -> europe | C10: =VLOOKUP(A10,p.greggio!A18:B75,2,FALSE) -> 3.6797548 | D10: =VLOOKUP(A10,p.raffinati!A18:B75,2,FALSE) -> 11.921719 | E10: =VLOOKUP(A10,p.coalignite!A18:B75,2,FALSE) -> 23.717419 | F10: =VLOOKUP(A10,p.gas!A18:B75,2,FALSE) -> 10.200716 | G10: =VLOOKUP(A10,p.ele!A18:B75,2,FALSE) -> 65.041962 | H10: =VLOOKUP(A10,s.elerinnov!A18:B75,2,FALSE)/100 -> 0.41270618 | I10: =VLOOKUP(A10,s.windsolar!A18:B75,2,FALSE)/100 -> 0.12522257 | J10: =VLOOKUP(A10,'co2'!A18:B75,2,FALSE) -> 68.56
A11: Spain | B11: =VLOOKUP(A11,region!$B$2:$M$198,2,FALSE) -> europe | C11: =VLOOKUP(A11,p.greggio!A19:B76,2,FALSE) -> 0.086914877 | D11: =VLOOKUP(A11,p.raffinati!A19:B76,2,FALSE) -> 67.674771 | E11: =VLOOKUP(A11,p.coalignite!A19:B76,2,FALSE) -> 1.900489 | F11: =VLOOKUP(A11,p.gas!A19:B76,2,FALSE) -> 0.096357159 | G11: =VLOOKUP(A11,p.ele!A19:B76,2,FALSE) -> 273.69417 | H11: =VLOOKUP(A11,s.elerinnov!A19:B76,2,FALSE)/100 -> 0.38622476 | I11: =VLOOKUP(A11,s.windsolar!A19:B76,2,FALSE)/100 -> 0.23256807 | J11: =VLOOKUP(A11,'co2'!A19:B76,2,FALSE) -> 254.99
A12: Sweden | B12: =VLOOKUP(A12,region!$B$2:$M$198,2,FALSE) -> europe | C12: =VLOOKUP(A12,p.greggio!A20:B77,2,FALSE) -> 0 | D12: =VLOOKUP(A12,p.raffinati!A20:B77,2,FALSE) -> 23.219468 | E12: =VLOOKUP(A12,p.coalignite!A20:B77,2,FALSE) -> 0.29890566 | F12: =VLOOKUP(A12,p.gas!A20:B77,2,FALSE) -> 0 | G12: =VLOOKUP(A12,p.ele!A20:B77,2,FALSE) -> 163.22107 | H12: =VLOOKUP(A12,s.elerinnov!A20:B77,2,FALSE)/100 -> 0.55270247 | I12: =VLOOKUP(A12,s.windsolar!A20:B77,2,FALSE)/100 -> 0.10393224 | J12: =VLOOKUP(A12,'co2'!A20:B77,2,FALSE) -> 39.22
A13: United Kingdom | B13: =VLOOKUP(A13,region!$B$2:$M$198,2,FALSE) -> europe | C13: =VLOOKUP(A13,p.greggio!A21:B78,2,FALSE) -> 50.788319 | D13: =VLOOKUP(A13,p.raffinati!A21:B78,2,FALSE) -> 59.150381 | E13: =VLOOKUP(A13,p.coalignite!A21:B78,2,FALSE) -> 2.5810018 | F13: =VLOOKUP(A13,p.gas!A21:B78,2,FALSE) -> 40.48256 | G13: =VLOOKUP(A13,p.ele!A21:B78,2,FALSE) -> 334.01236 | H13: =VLOOKUP(A13,s.elerinnov!A21:B78,2,FALSE)/100 -> 0.33984161 | I13: =VLOOKUP(A13,s.windsolar!A21:B78,2,FALSE)/100 -> 0.21020348 | J13: =VLOOKUP(A13,'co2'!A21:B78,2,FALSE) -> 361.76
... A15: Turkey | B15: =VLOOKUP(A15,region!$B$2:$M$198,2,FALSE) -> europe | C15: =VLOOKUP(A15,p.greggio!A23:B80,2,FALSE) -> 3.2700723 | D15: =VLOOKUP(A15,p.raffinati!A23:B80,2,FALSE) -> 29.023619 | E15: =VLOOKUP(A15,p.coalignite!A23:B80,2,FALSE) -> 84.739896 | F15: =VLOOKUP(A15,p.gas!A23:B80,2,FALSE) -> 0.50820124 | G15: =VLOOKUP(A15,p.ele!A23:B80,2,FALSE) -> 302.71011 | H15: =VLOOKUP(A15,s.elerinnov!A23:B80,2,FALSE)/100 -> 0.32375898 | I15: =VLOOKUP(A15,s.windsolar!A23:B80,2,FALSE)/100 -> 0.12025519 | J15: =VLOOKUP(A15,'co2'!A23:B80,2,FALSE) -> 385.26
A16: Kazakhstan | B16: =VLOOKUP(A16,region!$B$2:$M$198,2,FALSE) -> asia | C16: =VLOOKUP(A16,p.greggio!A25:B82,2,FALSE) -> 91.82151 | D16: =VLOOKUP(A16,p.raffinati!A25:B82,2,FALSE) -> 15.045257 | E16: =VLOOKUP(A16,p.coalignite!A25:B82,2,FALSE) -> 117.80644 | F16: =VLOOKUP(A16,p.gas!A25:B82,2,FALSE) -> 44.845805 | G16: =VLOOKUP(A16,p.ele!A24:B81,2,FALSE) -> 120.43379 | H16: =VLOOKUP(A16,s.elerinnov!A24:B81,2,FALSE)/100 -> 0.17797394 | I16: =VLOOKUP(A16,s.windsolar!A24:B81,2,FALSE)/100 -> 0.00497404 | J16: =VLOOKUP(A16,'co2'!A25:B82,2,FALSE) -> 246.8
A17: Russia | B17: =VLOOKUP(A17,region!$B$2:$M$198,2,FALSE) -> europe | C17: =VLOOKUP(A17,p.greggio!A26:B83,2,FALSE) -> 556.26843 | D17: =VLOOKUP(A17,p.raffinati!A26:B83,2,FALSE) -> 276.49036 | E17: =VLOOKUP(A17,p.coalignite!A26:B83,2,FALSE) -> 411.76858 | F17: =VLOOKUP(A17,p.gas!A26:B83,2,FALSE) -> 740.59285 | G17: =VLOOKUP(A17,p.ele!A25:B82,2,FALSE) -> 1127.8405 | H17: =VLOOKUP(A17,s.elerinnov!A25:B82,2,FALSE)/100 -> 0.17180802 | I17: =VLOOKUP(A17,s.windsolar!A25:B82,2,FALSE)/100 -> 0.00123083 | J17: =VLOOKUP(A17,'co2'!A26:B83,2,FALSE) -> 1754.59
A18: Ukraine | B18: =VLOOKUP(A18,region!$B$2:$M$198,2,FALSE) -> europe | C18: =VLOOKUP(A18,p.greggio!A27:B84,2,FALSE) -> 2.3224431 | D18: =VLOOKUP(A18,p.raffinati!A27:B84,2,FALSE) -> 2.7294132 | E18: =VLOOKUP(A18,p.coalignite!A27:B84,2,FALSE) -> 24.783543 | F18: =VLOOKUP(A18,p.gas!A27:B84,2,FALSE) -> 20.192242 | G18: =VLOOKUP(A18,p.ele!A26:B83,2,FALSE) -> 158.92771 | H18: =VLOOKUP(A18,s.elerinnov!A26:B83,2,FALSE)/100 -> 0.08810983 | I18: =VLOOKUP(A18,s.windsolar!A26:B83,2,FALSE)/100 -> 0.01226652 | J18: =VLOOKUP(A18,'co2'!A27:B84,2,FALSE) -> 174.79
A19: Uzbekistan | B19: =VLOOKUP(A19,region!$B$2:$M$198,2,FALSE) -> asia | C19: =VLOOKUP(A19,p.greggio!A28:B85,2,FALSE) -> 2.1824544 | D19: =VLOOKUP(A19,p.raffinati!A28:B85,2,FALSE) -> 2.118866 | E19: =VLOOKUP(A19,p.coalignite!A28:B85,2,FALSE) -> 4.6943515 | F19: =VLOOKUP(A19,p.gas!A28:B85,2,FALSE) -> 60.229157 | G19: =VLOOKUP(A19,p.ele!A27:B84,2,FALSE) -> 62.234072 | H19: =VLOOKUP(A19,s.elerinnov!A27:B84,2,FALSE)/100 -> 0.19132387 | I19: =VLOOKUP(A19,s.windsolar!A27:B84,2,FALSE)/100 -> 0 | J19: =VLOOKUP(A19,'co2'!A28:B85,2,FALSE) -> 92.05
A20: Canada | B20: =VLOOKUP(A20,region!$B$2:$M$198,2,FALSE) -> americas | C20: =VLOOKUP(A20,p.greggio!A31:B88,2,FALSE) -> 259.48123 | D20: =VLOOKUP(A20,p.raffinati!A31:B88,2,FALSE) -> 94.246527 | E20: =VLOOKUP(A20,p.coalignite!A31:B88,2,FALSE) -> 54.295462 | F20: =VLOOKUP(A20,p.gas!A31:B88,2,FALSE) -> 188.0717 | G20: =VLOOKUP(A20,p.ele!A28:B85,2,FALSE) -> 662.98609 | H20: =VLOOKUP(A20,s.elerinnov!A28:B85,2,FALSE)/100 -> 0.65860918 | I20: =VLOOKUP(A20,s.windsolar!A28:B85,2,FALSE)/100 -> 0.05296115 | J20: =VLOOKUP(A20,'co2'!A31:B88,2,FALSE) -> 596.29
A21: United States | B21: =VLOOKUP(A21,region!$B$2:$M$198,2,FALSE) -> americas | C21: =VLOOKUP(A21,p.greggio!A32:B89,2,FALSE) -> 675.98148 | D21: =VLOOKUP(A21,p.raffinati!A32:B89,2,FALSE) -> 895.90916 | E21: =VLOOKUP(A21,p.coalignite!A32:B89,2,FALSE) -> 683.74985 | F21: =VLOOKUP(A21,p.gas!A32:B89,2,FALSE) -> 864.07095 | G21: =VLOOKUP(A21,p.ele!A29:B86,2,FALSE) -> 4429.26 | H21: =VLOOKUP(A21,s.elerinnov!A29:B86,2,FALSE)/100 -> 0.17475512 | I21: =VLOOKUP(A21,s.windsolar!A29:B86,2,FALSE)/100 -> 0.08925479 | J21: =VLOOKUP(A21,'co2'!A32:B89,2,FALSE) -> 5117.77
A22: Argentina | B22: =VLOOKUP(A22,region!$B$2:$M$198,2,FALSE) -> americas | C22: =VLOOKUP(A22,p.greggio!A34:B91,2,FALSE) -> 27.944526 | D22: =VLOOKUP(A22,p.raffinati!A34:B91,2,FALSE) -> 28.721339 | E22: =VLOOKUP(A22,p.coalignite!A34:B91,2,FALSE) -> 0.01932 | F22: =VLOOKUP(A22,p.gas!A34:B91,2,FALSE) -> 45.28579 | G22: =VLOOKUP(A22,p.ele!A30:B87,2,FALSE) -> 148.17042 | H22: =VLOOKUP(A22,s.elerinnov!A30:B87,2,FALSE)/100 -> 0.30737978 | I22: =VLOOKUP(A22,s.windsolar!A30:B87,2,FALSE)/100 -> 0.00956281 | J22: =VLOOKUP(A22,'co2'!A34:B91,2,FALSE) -> 185.41
A23: Brazil | B23: =VLOOKUP(A23,region!$B$2:$M$198,2,FALSE) -> americas | C23: =VLOOKUP(A23,p.greggio!A35:B92,2,FALSE) -> 135.53103 | D23: =VLOOKUP(A23,p.raffinati!A35:B92,2,FALSE) -> 95.697308 | E23: =VLOOKUP(A23,p.coalignite!A35:B92,2,FALSE) -> 4.091682 | F23: =VLOOKUP(A23,p.gas!A35:B92,2,FALSE) -> 23.234643 | G23: =VLOOKUP(A23,p.ele!A31:B88,2,FALSE) -> 596.43544 | H23: =VLOOKUP(A23,s.elerinnov!A31:B88,2,FALSE)/100 -> 0.82457418 | I23: =VLOOKUP(A23,s.windsolar!A31:B88,2,FALSE)/100 -> 0.08753326 | J23: =VLOOKUP(A23,'co2'!A35:B92,2,FALSE) -> 419.5
A24: Chile | B24: =VLOOKUP(A24,region!$B$2:$M$198,2,FALSE) -> americas | C24: =VLOOKUP(A24,p.greggio!A36:B93,2,FALSE) -> 0.373 | D24: =VLOOKUP(A24,p.raffinati!A36:B93,2,FALSE) -> 9.4057062 | E24: =VLOOKUP(A24,p.coalignite!A36:B93,2,FALSE) -> 2.9632306 | F24: =VLOOKUP(A24,p.gas!A36:B93,2,FALSE) -> 1.5219993 | G24: =VLOOKUP(A24,p.ele!A32:B89,2,FALSE) -> 80.548309 | H24: =VLOOKUP(A24,s.elerinnov!A32:B89,2,FALSE)/100 -> 0.46835038 | I24: =VLOOKUP(A24,s.windsolar!A32:B89,2,FALSE)/100 -> 0.11067327 | J24: =VLOOKUP(A24,'co2'!A36:B93,2,FALSE) -> 88.88
A25: Colombia | B25: =VLOOKUP(A25,region!$B$2:$M$198,2,FALSE) -> americas | C25: =VLOOKUP(A25,p.greggio!A37:B94,2,FALSE) -> 44.590009 | D25: =VLOOKUP(A25,p.raffinati!A37:B94,2,FALSE) -> 19.39399 | E25: =VLOOKUP(A25,p.coalignite!A37:B94,2,FALSE) -> 84.30001 | F25: =VLOOKUP(A25,p.gas!A37:B94,2,FALSE) -> 12.666634 | G25: =VLOOKUP(A25,p.ele!A33:B90,2,FALSE) -> 80.277083 | H25: =VLOOKUP(A25,s.elerinnov!A33:B90,2,FALSE)/100 -> 0.75728799 | I25: =VLOOKUP(A25,s.windsolar!A33:B90,2,FALSE)/100 -> 0.00054229 | J25: =VLOOKUP(A25,'co2'!A37:B94,2,FALSE) -> 76.49
A26: Mexico | B26: =VLOOKUP(A26,region!$B$2:$M$198,2,FALSE) -> americas | C26: =VLOOKUP(A26,p.greggio!A38:B95,2,FALSE) -> 101.57925 | D26: =VLOOKUP(A26,p.raffinati!A38:B95,2,FALSE) -> 35.620669 | E26: =VLOOKUP(A26,p.coalignite!A38:B95,2,FALSE) -> 15.960486 | F26: =VLOOKUP(A26,p.gas!A38:B95,2,FALSE) -> 29.738979 | G26: =VLOOKUP(A26,p.ele!A34:B91,2,FALSE) -> 320.15604 | H26: =VLOOKUP(A26,s.elerinnov!A34:B91,2,FALSE)/100 -> 0.16738463 | I26: =VLOOKUP(A26,s.windsolar!A34:B91,2,FALSE)/100 -> 0.06282974 | J26: =VLOOKUP(A26,'co2'!A38:B95,2,FALSE) -> 429.92
A27: Venezuela | B27: =VLOOKUP(A27,region!$B$2:$M$198,2,FALSE) -> americas | C27: =VLOOKUP(A27,p.greggio!A39:B96,2,FALSE) -> 81.018287 | D27: =VLOOKUP(A27,p.raffinati!A39:B96,2,FALSE) -> 30.254763 | E27: =VLOOKUP(A27,p.coalignite!A39:B96,2,FALSE) -> 0.41130712 | F27: =VLOOKUP(A27,p.gas!A39:B96,2,FALSE) -> 20.941609 | G27: =VLOOKUP(A27,p.ele!A35:B92,2,FALSE) -> 100.31699 | H27: =VLOOKUP(A27,s.elerinnov!A35:B92,2,FALSE)/100 -> 0.70765884 | I27: =VLOOKUP(A27,s.windsolar!A35:B92,2,FALSE)/100 -> 0 | J27: =VLOOKUP(A27,'co2'!A39:B96,2,FALSE) -> 103.29
A28: China | B28: =VLOOKUP(A28,region!$B$2:$M$198,2,FALSE) -> asia | C28: =VLOOKUP(A28,p.greggio!A41:B98,2,FALSE) -> 192.54692 | D28: =VLOOKUP(A28,p.raffinati!A41:B98,2,FALSE) -> 595.34223 | E28: =VLOOKUP(A28,p.coalignite!A41:B98,2,FALSE) -> 3474.4865 | F28: =VLOOKUP(A28,p.gas!A41:B98,2,FALSE) -> 160.37922 | G28: =VLOOKUP(A28,p.ele!A36:B93,2,FALSE) -> 7091.7903 | H28: =VLOOKUP(A28,s.elerinnov!A36:B93,2,FALSE)/100 -> 0.26254638 | I28: =VLOOKUP(A28,s.windsolar!A36:B93,2,FALSE)/100 -> 0.07748251 | J28: =VLOOKUP(A28,'co2'!A41:B98,2,FALSE) -> 9466.5
A29: India | B29: =VLOOKUP(A29,region!$B$2:$M$198,2,FALSE) -> asia | C29: =VLOOKUP(A29,p.greggio!A42:B99,2,FALSE) -> 38.599272 | D29: =VLOOKUP(A29,p.raffinati!A42:B99,2,FALSE) -> 274.37854 | E29: =VLOOKUP(A29,p.coalignite!A42:B99,2,FALSE) -> 763.67761 | F29: =VLOOKUP(A29,p.gas!A42:B99,2,FALSE) -> 32.127425 | G29: =VLOOKUP(A29,p.ele!A37:B94,2,FALSE) -> 1643.1696 | H29: =VLOOKUP(A29,s.elerinnov!A37:B94,2,FALSE)/100 -> 0.18505005 | I29: =VLOOKUP(A29,s.windsolar!A37:B94,2,FALSE)/100 -> 0.06396329 | J29: =VLOOKUP(A29,'co2'!A42:B99,2,FALSE) -> 2276.95
A30: Indonesia | B30: =VLOOKUP(A30,region!$B$2:$M$198,2,FALSE) -> asia | C30: =VLOOKUP(A30,p.greggio!A43:B100,2,FALSE) -> 38.948682 | D30: =VLOOKUP(A30,p.raffinati!A43:B100,2,FALSE) -> 49.110417 | E30: =VLOOKUP(A30,p.coalignite!A43:B100,2,FALSE) -> 474.18283 | F30: =VLOOKUP(A30,p.gas!A43:B100,2,FALSE) -> 74.83979 | G30: =VLOOKUP(A30,p.ele!A38:B95,2,FALSE) -> 268.35614 | H30: =VLOOKUP(A30,s.elerinnov!A38:B95,2,FALSE)/100 -> 0.12459515 | I30: =VLOOKUP(A30,s.windsolar!A38:B95,2,FALSE)/100 -> 0.05205286 | J30: =VLOOKUP(A30,'co2'!A43:B100,2,FALSE) -> 522.23
A31: Japan | B31: =VLOOKUP(A31,region!$B$2:$M$198,2,FALSE) -> asia | C31: =VLOOKUP(A31,p.greggio!A44:B101,2,FALSE) -> 0.3775516 | D31: =VLOOKUP(A31,p.raffinati!A44:B101,2,FALSE) -> 149.49179 | E31: =VLOOKUP(A31,p.coalignite!A44:B101,2,FALSE) -> 0.98953039 | F31: =VLOOKUP(A31,p.gas!A44:B101,2,FALSE) -> 2.7405375 | G31: =VLOOKUP(A31,p.ele!A39:B96,2,FALSE) -> 1101.8926 | H31: =VLOOKUP(A31,s.elerinnov!A39:B96,2,FALSE)/100 -> 0.17503569 | I31: =VLOOKUP(A31,s.windsolar!A39:B96,2,FALSE)/100 -> 0.09587379 | J31: =VLOOKUP(A31,'co2'!A44:B101,2,FALSE) -> 1123.04
A32: Malaysia | B32: =VLOOKUP(A32,region!$B$2:$M$198,2,FALSE) -> asia | C32: =VLOOKUP(A32,p.greggio!A45:B102,2,FALSE) -> 34.185604 | D32: =VLOOKUP(A32,p.raffinati!A45:B102,2,FALSE) -> 24.58658 | E32: =VLOOKUP(A32,p.coalignite!A45:B102,2,FALSE) -> 2.4816485 | F32: =VLOOKUP(A32,p.gas!A45:B102,2,FALSE) -> 67.262482 | G32: =VLOOKUP(A32,p.ele!A40:B97,2,FALSE) -> 166.38167 | H32: =VLOOKUP(A32,s.elerinnov!A40:B97,2,FALSE)/100 -> 0.14458234 | I32: =VLOOKUP(A32,s.windsolar!A40:B97,2,FALSE)/100 -> 0.00260376 | J32: =VLOOKUP(A32,'co2'!A45:B102,2,FALSE) -> 236.1
A33: South Korea | B33: =VLOOKUP(A33,region!$B$2:$M$198,2,FALSE) -> asia | C33: =VLOOKUP(A33,p.greggio!A46:B103,2,FALSE) -> 0.74822061 | D33: =VLOOKUP(A33,p.raffinati!A46:B103,2,FALSE) -> 158.71838 | E33: =VLOOKUP(A33,p.coalignite!A46:B103,2,FALSE) -> 1.2 | F33: =VLOOKUP(A33,p.gas!A46:B103,2,FALSE) -> 0.30538965 | G33: =VLOOKUP(A33,p.ele!A41:B98,2,FALSE) -> 593.34603 | H33: =VLOOKUP(A33,s.elerinnov!A41:B98,2,FALSE)/100 -> 0.04424974 | I33: =VLOOKUP(A33,s.windsolar!A41:B98,2,FALSE)/100 -> 0.02181469 | J33: =VLOOKUP(A33,'co2'!A46:B103,2,FALSE) -> 703.99
A34: Taiwan | B34: =VLOOKUP(A34,region!$B$2:$M$198,2,FALSE) -> asia | C34: =VLOOKUP(A34,p.greggio!A47:B104,2,FALSE) -> 0.00432335 | D34: =VLOOKUP(A34,p.raffinati!A47:B104,2,FALSE) -> 44.883748 | E34: =VLOOKUP(A34,p.coalignite!A47:B104,2,FALSE) -> 0 | F34: =VLOOKUP(A34,p.gas!A47:B104,2,FALSE) -> 0.17762991 | G34: =VLOOKUP(A34,p.ele!A42:B99,2,FALSE) -> 273.60661 | H34: =VLOOKUP(A34,s.elerinnov!A42:B99,2,FALSE)/100 -> 0.0521132 | I34: =VLOOKUP(A34,s.windsolar!A42:B99,2,FALSE)/100 -> 0.01615383 | J34: =VLOOKUP(A34,'co2'!A47:B104,2,FALSE) -> 281.81
A35: Thailand | B35: =VLOOKUP(A35,region!$B$2:$M$198,2,FALSE) -> asia | C35: =VLOOKUP(A35,p.greggio!A48:B105,2,FALSE) -> 17.077939 | D35: =VLOOKUP(A35,p.raffinati!A48:B105,2,FALSE) -> 67.960116 | E35: =VLOOKUP(A35,p.coalignite!A48:B105,2,FALSE) -> 14.852282 | F35: =VLOOKUP(A35,p.gas!A48:B105,2,FALSE) -> 29.707371 | G35: =VLOOKUP(A35,p.ele!A43:B100,2,FALSE) -> 188.98789 | H35: =VLOOKUP(A35,s.elerinnov!A43:B100,2,FALSE)/100 -> 0.20196272 | I35: =VLOOKUP(A35,s.windsolar!A43:B100,2,FALSE)/100 -> 0.03368271 | J35: =VLOOKUP(A35,'co2'!A48:B105,2,FALSE) -> 268.22
A36: Australia | B36: =VLOOKUP(A36,region!$B$2:$M$198,2,FALSE) -> asia | C36: =VLOOKUP(A36,p.greggio!A50:B107,2,FALSE) -> 15.797466 | D36: =VLOOKUP(A36,p.raffinati!A50:B107,2,FALSE) -> 23.376451 | E36: =VLOOKUP(A36,p.coalignite!A50:B107,2,FALSE) -> 501.98727 | F36: =VLOOKUP(A36,p.gas!A50:B107,2,FALSE) -> 125.01838 | G36: =VLOOKUP(A36,p.ele!A44:B101,2,FALSE) -> 258.99399 | H36: =VLOOKUP(A36,s.elerinnov!A44:B101,2,FALSE)/100 -> 0.19604814 | I36: =VLOOKUP(A36,s.windsolar!A44:B101,2,FALSE)/100 -> 0.10146843 | J36: =VLOOKUP(A36,'co2'!A50:B107,2,FALSE) -> 403.11
A37: New Zealand | B37: =VLOOKUP(A37,region!$B$2:$M$198,2,FALSE) -> asia | C37: =VLOOKUP(A37,p.greggio!A51:B108,2,FALSE) -> 1.2733076 | D37: =VLOOKUP(A37,p.raffinati!A51:B108,2,FALSE) -> 5.6860093 | E37: =VLOOKUP(A37,p.coalignite!A51:B108,2,FALSE) -> 3.2139412 | F37: =VLOOKUP(A37,p.gas!A51:B108,2,FALSE) -> 4.2525485 | G37: =VLOOKUP(A37,p.ele!A45:B102,2,FALSE) -> 43.612477 | H37: =VLOOKUP(A37,s.elerinnov!A45:B102,2,FALSE)/100 -> 0.83072439 | I37: =VLOOKUP(A37,s.windsolar!A45:B102,2,FALSE)/100 -> 0.21944132 | J37: =VLOOKUP(A37,'co2'!A51:B108,2,FALSE) -> 31.12
A38: Algeria | B38: =VLOOKUP(A38,region!$B$2:$M$198,2,FALSE) -> africa | C38: =VLOOKUP(A38,p.greggio!A53:B110,2,FALSE) -> 65.795608 | D38: =VLOOKUP(A38,p.raffinati!A53:B110,2,FALSE) -> 38.349553 | E38: =VLOOKUP(A38,p.coalignite!A53:B110,2,FALSE) -> 0 | F38: =VLOOKUP(A38,p.gas!A53:B110,2,FALSE) -> 95.948095 | G38: =VLOOKUP(A38,p.ele!A46:B103,2,FALSE) -> 86.604925 | H38: =VLOOKUP(A38,s.elerinnov!A46:B103,2,FALSE)/100 -> 0.00647841 | I38: =VLOOKUP(A38,s.windsolar!A46:B103,2,FALSE)/100 -> 0.0045206 | J38: =VLOOKUP(A38,'co2'!A53:B110,2,FALSE) -> 143.76
A39: Egypt | B39: =VLOOKUP(A39,region!$B$2:$M$198,2,FALSE) -> africa | C39: =VLOOKUP(A39,p.greggio!A54:B111,2,FALSE) -> 32.718133 | D39: =VLOOKUP(A39,p.raffinati!A54:B111,2,FALSE) -> 26.926385 | E39: =VLOOKUP(A39,p.coalignite!A54:B111,2,FALSE) -> 0 | F39: =VLOOKUP(A39,p.gas!A54:B111,2,FALSE) -> 53.641717 | G39: =VLOOKUP(A39,p.ele!A47:B104,2,FALSE) -> 206.56807 | H39: =VLOOKUP(A39,s.elerinnov!A47:B104,2,FALSE)/100 -> 0.08208707 | I39: =VLOOKUP(A39,s.windsolar!A47:B104,2,FALSE)/100 -> 0.01630861 | J39: =VLOOKUP(A39,'co2'!A54:B111,2,FALSE) -> 212.8
A40: Nigeria | B40: =VLOOKUP(A40,region!$B$2:$M$198,2,FALSE) -> africa | C40: =VLOOKUP(A40,p.greggio!A55:B112,2,FALSE) -> 101.34027 | D40: =VLOOKUP(A40,p.raffinati!A55:B112,2,FALSE) -> 4.1462033 | E40: =VLOOKUP(A40,p.coalignite!A55:B112,2,FALSE) -> 0.046 | F40: =VLOOKUP(A40,p.gas!A55:B112,2,FALSE) -> 44.490119 | G40: =VLOOKUP(A40,p.ele!A48:B105,2,FALSE) -> 33.30956 | H40: =VLOOKUP(A40,s.elerinnov!A48:B105,2,FALSE)/100 -> 0.16724692 | I40: =VLOOKUP(A40,s.windsolar!A48:B105,2,FALSE)/100 -> 0 | J40: =VLOOKUP(A40,'co2'!A55:B112,2,FALSE) -> 99.38
A41: South Africa | B41: =VLOOKUP(A41,region!$B$2:$M$198,2,FALSE) -> africa | C41: =VLOOKUP(A41,p.greggio!A56:B113,2,FALSE) -> 4.5788634 | D41: =VLOOKUP(A41,p.raffinati!A56:B113,2,FALSE) -> 21.729593 | E41: =VLOOKUP(A41,p.coalignite!A56:B113,2,FALSE) -> 256.99899 | F41: =VLOOKUP(A41,p.gas!A56:B113,2,FALSE) -> 0.95127586 | G41: =VLOOKUP(A41,p.ele!A49:B106,2,FALSE) -> 255.96501 | H41: =VLOOKUP(A41,s.elerinnov!A49:B106,2,FALSE)/100 -> 0.0528614 | I41: =VLOOKUP(A41,s.windsolar!A49:B106,2,FALSE)/100 -> 0.03193159 | J41: =VLOOKUP(A41,'co2'!A56:B113,2,FALSE) -> 427.73
...

Sheet codebook
A1: Nome Variabile | B1: Descrizione Variabile | C1: Valori | D1: Tipo
A2: country | B2: Nome del Paese | C2: Nome del Paese | D2: Qualitativo sconnesso
A3: region | B3: Macroarea geografica del Paese | C3: Africa, America, Asia, Europa | D3: Qualitativo categorica
A4: p.greggio | B4: Produzione di greggio (Mt) | C4: Numerica: 0 valore minimo, - | D4: Quantitativa continua
A5: p.raffinati | B5: Produzione di raffinati (Mt) | C5: Numerica: 0 valore minimo, - | D5: Quantitativa continua
A6: p.coalignite | B6: Produzione di carbone e lignite (Mt) | C6: Numerica: 0 valore minimo, - | D6: Quantitativa continua
A7: p.gas | B7: Produzione di gas naturali (bcm) | C7: Numerica: 0 valore minimo, - | D7: Quantitativa continua
A8: p.ele | B8: Produzione di energia elettrica (TWh) | C8: Numerica: 0 valore minimo, - | D8: Quantitativa continua
A9: s.elerinnov | B9: Percentuale di energia rinnovabile sul totale di energia elettrica (%) | C9: Numerica: 0 valore minimo, 100 valore massimo | D9: Quantitativa continua
A10: s.windsolr | B10: Percentuale di energia eolica e solare sul totale di energia elettrica prodotta (%) | C10: Numerica: 0 valore minimo, 100 valore massimo | D10: Quantitativa continua
A11: co2 | B11: Emissioni di CO derivanti dalla combustione di carburanti (Mt) | C11: Numerica: 0 valore minimo, - | D11: Quantitativa continua
B13: Mt: Megatonnelate | 1,0e+09 Chilogrammi
B14: bcm: billion cubic metres (miliardo di metri cubi)
B15: TWh: Terawattora | 1,0e+12 Wattora
